2025-10-20 17:49:01,537 INFO    MainThread:44209 [wandb_setup.py:_flush():81] Current SDK version is 0.22.2
2025-10-20 17:49:01,537 INFO    MainThread:44209 [wandb_setup.py:_flush():81] Configure stats pid to 44209
2025-10-20 17:49:01,537 INFO    MainThread:44209 [wandb_setup.py:_flush():81] Loading settings from /Users/santhoshtanay/.config/wandb/settings
2025-10-20 17:49:01,537 INFO    MainThread:44209 [wandb_setup.py:_flush():81] Loading settings from /Users/santhoshtanay/Desktop/momeet/vgg6_cifar_full_bundle/wandb/settings
2025-10-20 17:49:01,537 INFO    MainThread:44209 [wandb_setup.py:_flush():81] Loading settings from environment variables
2025-10-20 17:49:01,537 INFO    MainThread:44209 [wandb_init.py:setup_run_log_directory():705] Logging user logs to /Users/santhoshtanay/Desktop/momeet/vgg6_cifar_full_bundle/wandb/run-20251020_174901-iynnq4w0/logs/debug.log
2025-10-20 17:49:01,537 INFO    MainThread:44209 [wandb_init.py:setup_run_log_directory():706] Logging internal logs to /Users/santhoshtanay/Desktop/momeet/vgg6_cifar_full_bundle/wandb/run-20251020_174901-iynnq4w0/logs/debug-internal.log
2025-10-20 17:49:01,537 INFO    MainThread:44209 [wandb_init.py:init():832] calling init triggers
2025-10-20 17:49:01,537 INFO    MainThread:44209 [wandb_init.py:init():837] wandb.init called with sweep_config: {}
config: {'data_dir': './data', 'out_dir': './runs/act_silu', 'activation': 'silu', 'dropout': 0.3, 'epochs': 40, 'batch_size': 128, 'optimizer': 'sgd', 'lr': 0.1, 'momentum': 0.9, 'weight_decay': 0.0005, 'label_smoothing': 0.0, 'amp': True, 'seed': 42, 'num_workers': 8, 'aug_hflip': True, 'aug_crop': True, 'aug_cutout': True, 'aug_jitter': True, 'wandb': True, 'wandb_project': 'vgg6-cifar10-assignment', 'wandb_group': 'q2-sweeps', 'run_name': None, '_wandb': {}}
2025-10-20 17:49:01,537 INFO    MainThread:44209 [wandb_init.py:init():880] starting backend
2025-10-20 17:49:01,758 INFO    MainThread:44209 [wandb_init.py:init():883] sending inform_init request
2025-10-20 17:49:01,790 INFO    MainThread:44209 [wandb_init.py:init():891] backend started and connected
2025-10-20 17:49:01,792 INFO    MainThread:44209 [wandb_init.py:init():961] updated telemetry
2025-10-20 17:49:01,805 INFO    MainThread:44209 [wandb_init.py:init():985] communicating run to backend with 90.0 second timeout
2025-10-20 17:49:02,646 INFO    MainThread:44209 [wandb_init.py:init():1036] starting run threads in backend
2025-10-20 17:49:02,678 INFO    MainThread:44209 [wandb_run.py:_console_start():2509] atexit reg
2025-10-20 17:49:02,678 INFO    MainThread:44209 [wandb_run.py:_redirect():2357] redirect: wrap_raw
2025-10-20 17:49:02,678 INFO    MainThread:44209 [wandb_run.py:_redirect():2426] Wrapping output streams.
2025-10-20 17:49:02,678 INFO    MainThread:44209 [wandb_run.py:_redirect():2449] Redirects installed.
2025-10-20 17:49:02,686 INFO    MainThread:44209 [wandb_init.py:init():1076] run started, returning control to user process
2025-10-20 17:52:43,426 INFO    wandb-AsyncioManager-main:44209 [service_client.py:_forward_responses():80] Reached EOF.
2025-10-20 17:52:43,426 INFO    wandb-AsyncioManager-main:44209 [mailbox.py:close():137] Closing mailbox, abandoning 2 handles.
2025-10-20 17:52:45,142 ERROR   MainThread:44209 [redirect.py:_on_write():664] [all runs] error in stderr callback
Traceback (most recent call last):
  File "/Users/santhoshtanay/Desktop/momeet/vgg6_cifar_full_bundle/.venv/lib/python3.13/site-packages/wandb/sdk/lib/redirect.py", line 662, in _on_write
    cb(written_data)
    ~~^^^^^^^^^^^^^^
  File "/Users/santhoshtanay/Desktop/momeet/vgg6_cifar_full_bundle/.venv/lib/python3.13/site-packages/wandb/sdk/wandb_run.py", line 2436, in <lambda>
    lambda data: self._console_raw_callback("stderr", data),
                 ~~~~~~~~~~~~~~~~~~~~~~~~~~^^^^^^^^^^^^^^^^
  File "/Users/santhoshtanay/Desktop/momeet/vgg6_cifar_full_bundle/.venv/lib/python3.13/site-packages/wandb/sdk/wandb_run.py", line 399, in wrapper
    return func(self, *args, **kwargs)
  File "/Users/santhoshtanay/Desktop/momeet/vgg6_cifar_full_bundle/.venv/lib/python3.13/site-packages/wandb/sdk/wandb_run.py", line 457, in wrapper_fn
    return func(self, *args, **kwargs)
  File "/Users/santhoshtanay/Desktop/momeet/vgg6_cifar_full_bundle/.venv/lib/python3.13/site-packages/wandb/sdk/wandb_run.py", line 1595, in _console_raw_callback
    self._backend.interface.publish_output_raw(name, data)
    ~~~~~~~~~~~~~~~~~~~~~~~~~~~~~~~~~~~~~~~~~~^^^^^^^^^^^^
  File "/Users/santhoshtanay/Desktop/momeet/vgg6_cifar_full_bundle/.venv/lib/python3.13/site-packages/wandb/sdk/interface/interface.py", line 802, in publish_output_raw
    self._publish_output_raw(o)
    ~~~~~~~~~~~~~~~~~~~~~~~~^^^
  File "/Users/santhoshtanay/Desktop/momeet/vgg6_cifar_full_bundle/.venv/lib/python3.13/site-packages/wandb/sdk/interface/interface_shared.py", line 37, in _publish_output_raw
    self._publish(rec)
    ~~~~~~~~~~~~~^^^^^
  File "/Users/santhoshtanay/Desktop/momeet/vgg6_cifar_full_bundle/.venv/lib/python3.13/site-packages/wandb/sdk/interface/interface_sock.py", line 43, in _publish
    self._asyncer.run(lambda: self._client.publish(request))
    ~~~~~~~~~~~~~~~~~^^^^^^^^^^^^^^^^^^^^^^^^^^^^^^^^^^^^^^^
  File "/Users/santhoshtanay/Desktop/momeet/vgg6_cifar_full_bundle/.venv/lib/python3.13/site-packages/wandb/sdk/lib/asyncio_manager.py", line 136, in run
    return future.result()
           ~~~~~~~~~~~~~^^
  File "/Library/Frameworks/Python.framework/Versions/3.13/lib/python3.13/concurrent/futures/_base.py", line 456, in result
    return self.__get_result()
           ~~~~~~~~~~~~~~~~~^^
  File "/Library/Frameworks/Python.framework/Versions/3.13/lib/python3.13/concurrent/futures/_base.py", line 401, in __get_result
    raise self._exception
  File "/Users/santhoshtanay/Desktop/momeet/vgg6_cifar_full_bundle/.venv/lib/python3.13/site-packages/wandb/sdk/lib/asyncio_manager.py", line 219, in _wrap
    return await fn()
           ^^^^^^^^^^
  File "/Users/santhoshtanay/Desktop/momeet/vgg6_cifar_full_bundle/.venv/lib/python3.13/site-packages/wandb/sdk/lib/service/service_client.py", line 38, in publish
    await self._send_server_request(request)
  File "/Users/santhoshtanay/Desktop/momeet/vgg6_cifar_full_bundle/.venv/lib/python3.13/site-packages/wandb/sdk/lib/service/service_client.py", line 64, in _send_server_request
    await self._writer.drain()
  File "/Library/Frameworks/Python.framework/Versions/3.13/lib/python3.13/asyncio/streams.py", line 386, in drain
    await self._protocol._drain_helper()
  File "/Library/Frameworks/Python.framework/Versions/3.13/lib/python3.13/asyncio/streams.py", line 166, in _drain_helper
    raise ConnectionResetError('Connection lost')
ConnectionResetError: Connection lost
2025-10-20 17:52:45,152 ERROR   MainThread:44209 [redirect.py:_on_write():664] [all runs] error in stderr callback
Traceback (most recent call last):
  File "/Users/santhoshtanay/Desktop/momeet/vgg6_cifar_full_bundle/.venv/lib/python3.13/site-packages/wandb/sdk/lib/redirect.py", line 662, in _on_write
    cb(written_data)
    ~~^^^^^^^^^^^^^^
  File "/Users/santhoshtanay/Desktop/momeet/vgg6_cifar_full_bundle/.venv/lib/python3.13/site-packages/wandb/sdk/wandb_run.py", line 2436, in <lambda>
    lambda data: self._console_raw_callback("stderr", data),
                 ~~~~~~~~~~~~~~~~~~~~~~~~~~^^^^^^^^^^^^^^^^
  File "/Users/santhoshtanay/Desktop/momeet/vgg6_cifar_full_bundle/.venv/lib/python3.13/site-packages/wandb/sdk/wandb_run.py", line 399, in wrapper
    return func(self, *args, **kwargs)
  File "/Users/santhoshtanay/Desktop/momeet/vgg6_cifar_full_bundle/.venv/lib/python3.13/site-packages/wandb/sdk/wandb_run.py", line 457, in wrapper_fn
    return func(self, *args, **kwargs)
  File "/Users/santhoshtanay/Desktop/momeet/vgg6_cifar_full_bundle/.venv/lib/python3.13/site-packages/wandb/sdk/wandb_run.py", line 1595, in _console_raw_callback
    self._backend.interface.publish_output_raw(name, data)
    ~~~~~~~~~~~~~~~~~~~~~~~~~~~~~~~~~~~~~~~~~~^^^^^^^^^^^^
  File "/Users/santhoshtanay/Desktop/momeet/vgg6_cifar_full_bundle/.venv/lib/python3.13/site-packages/wandb/sdk/interface/interface.py", line 802, in publish_output_raw
    self._publish_output_raw(o)
    ~~~~~~~~~~~~~~~~~~~~~~~~^^^
  File "/Users/santhoshtanay/Desktop/momeet/vgg6_cifar_full_bundle/.venv/lib/python3.13/site-packages/wandb/sdk/interface/interface_shared.py", line 37, in _publish_output_raw
    self._publish(rec)
    ~~~~~~~~~~~~~^^^^^
  File "/Users/santhoshtanay/Desktop/momeet/vgg6_cifar_full_bundle/.venv/lib/python3.13/site-packages/wandb/sdk/interface/interface_sock.py", line 43, in _publish
    self._asyncer.run(lambda: self._client.publish(request))
    ~~~~~~~~~~~~~~~~~^^^^^^^^^^^^^^^^^^^^^^^^^^^^^^^^^^^^^^^
  File "/Users/santhoshtanay/Desktop/momeet/vgg6_cifar_full_bundle/.venv/lib/python3.13/site-packages/wandb/sdk/lib/asyncio_manager.py", line 136, in run
    return future.result()
           ~~~~~~~~~~~~~^^
  File "/Library/Frameworks/Python.framework/Versions/3.13/lib/python3.13/concurrent/futures/_base.py", line 456, in result
    return self.__get_result()
           ~~~~~~~~~~~~~~~~~^^
  File "/Library/Frameworks/Python.framework/Versions/3.13/lib/python3.13/concurrent/futures/_base.py", line 401, in __get_result
    raise self._exception
  File "/Users/santhoshtanay/Desktop/momeet/vgg6_cifar_full_bundle/.venv/lib/python3.13/site-packages/wandb/sdk/lib/asyncio_manager.py", line 219, in _wrap
    return await fn()
           ^^^^^^^^^^
  File "/Users/santhoshtanay/Desktop/momeet/vgg6_cifar_full_bundle/.venv/lib/python3.13/site-packages/wandb/sdk/lib/service/service_client.py", line 38, in publish
    await self._send_server_request(request)
  File "/Users/santhoshtanay/Desktop/momeet/vgg6_cifar_full_bundle/.venv/lib/python3.13/site-packages/wandb/sdk/lib/service/service_client.py", line 64, in _send_server_request
    await self._writer.drain()
  File "/Library/Frameworks/Python.framework/Versions/3.13/lib/python3.13/asyncio/streams.py", line 386, in drain
    await self._protocol._drain_helper()
  File "/Library/Frameworks/Python.framework/Versions/3.13/lib/python3.13/asyncio/streams.py", line 166, in _drain_helper
    raise ConnectionResetError('Connection lost')
ConnectionResetError: Connection lost
